Workbook

Sheet Income Statement
A1: SUN PHARMACEUTICAL INDUSTRIES LTD – CONSOLIDATED INCOME STATEMENT (₹ in Millions)
C2: FY2022 | D2: FY2023 | E2: FY2024
A3: REVENUE
A4: Revenue from contracts with customers | C4: 384264.2 | D4: 432788.7 | E4: 477584.5
A5: Other operating revenues | C5: 2280.7 | D5: 6068.1 | E5: 7384
A6: Total Revenue from Operations | C6: =SUM(C4:C5) -> 386544.9 | D6: =SUM(D4:D5) -> 438856.8 | E6: =SUM(E4:E5) -> 484968.5
A7: Other income | C7: 9215.1 | D7: 6345.2 | E7: 13541.9
A8: Total Income | C8: =C6+C7 -> 395760 | D8: =D6+D7 -> 445202 | E8: =E6+E7 -> 498510.4
A10: EXPENSES
A11: Cost of materials consumed | C11: 70491.2 | D11: 77775.7 | E11: 69043.3
A12: Purchases of stock-in-trade | C12: 34100.3 | D12: 35715 | E12: 34661.5
A13: Changes in inventories | C13: -1076.1 | D13: -6869.1 | E13: 2921.3
A14: Employee benefits expense | C14: 73008.3 | D14: 82960.3 | E14: 94290.6
A15: Finance costs | C15: 1273.5 | D15: 1720 | E15: 2384.7
A16: Depreciation & amortisation | C16: 21437.4 | D16: 25294.3 | E16: 25566.4
A17: Other expenses | C17: 107583.6 | D17: 131546 | E17: 154181.8
A18: Net FX (gain)/loss | C18: -236.5 | D18: 1261 | E18: -361.3
A19: Total Expenses | C19: =SUM(C11:C18) -> 306581.7 | D19: =SUM(D11:D18) -> 349403.2 | E19: =SUM(E11:E18) -> 382688.3
A21: PROFITABILITY
A22: EBIT (Profit before exceptional items & tax) | C22: 90481.4 | D22: 95798.8 | E22: 115822.1
A23: Exceptional items (net) | C23: 45668.2 | D23: 1714.5 | E23: 4943.2
A24: Profit before tax (PBT) | C24: 44813.2 | D24: 94084.3 | E24: 110878.9
A25: Tax expense | C25: 10755 | D25: 8475.9 | E25: 14394.5
A26: Profit after tax (PAT) – before NCI & assoc | C26: =C24-C25 -> 34058.2 | D26: =D24-D25 -> 85608.4 | E26: =E24-E25 -> 96484.4
A27: Share of profit/(loss) of associates & JV | C27: -165.4 | D27: -479 | E27: -384.1
A28: Non-controlling interests | C28: 1165.5 | D28: 393.6 | E28: 336.5
A29: PAT attributable to owners of the Company | C29: =C26+C27-C28 -> 32727.3 | D29: =D26+D27-D28 -> 84735.8 | E29: =E26+E27-E28 -> 95763.8
A31: MARGIN ANALYSIS
A32: EBITDA margin ((EBIT + Dep) / Rev from Ops) | C32: =(C22+C16)/C6 -> 0.28953635 | D32: =(D22+D16)/D6 -> 0.2759285 | E32: =(E22+E16)/E6 -> 0.29154162
A33: EBIT margin (EBIT / Rev from Ops) | C33: =C22/C6 -> 0.23407733 | D33: =D22/D6 -> 0.21829171 | E33: =E22/E6 -> 0.23882396
A34: PAT margin (owners) (PAT / Rev from Ops) | C34: =C29/C6 -> 0.084666232 | D34: =D29/D6 -> 0.19308303 | E34: =E29/E6 -> 0.19746396
A35: Effective tax rate (Tax / PBT) | C35: =C25/C24 -> 0.23999625 | D35: =D25/D24 -> 0.090088357 | E35: =E25/E24 -> 0.12982181

Sheet Balance Sheet
A1: SUN PHARMACEUTICAL INDUSTRIES LTD – CONSOLIDATED BALANCE SHEET (₹ in Millions)
C2: FY2022 | D2: FY2023 | E2: FY2024
A3: ASSETS
A4: Non-Current Assets
A5: Property, plant & equipment | C5: 102349.9 | D5: 103903.8 | E5: 101923.2
A6: Capital work-in-progress | C6: 9365.2 | D6: 9633.5 | E6: 11077.3
A7: Goodwill (net) | C7: 62876.4 | D7: 83580.3 | E7: 85989.5
A8: Other intangible assets | C8: 50303.5 | D8: 53170.3 | E8: 44201.1
A9: Intangible assets under development | C9: 6303.1 | D9: 40098.1 | E9: 42461.5
A10: Investments (associates, JV) | C10: 2605.6 | D10: 3836.4 | E10: 4426.1
A11: Financial investments (non-current) | C11: 62218.3 | D11: 50680.9 | E11: 59986.2
A12: Deferred tax assets (net) | C12: 35564.4 | D12: 35189.2 | E12: 41036.5
A13: Income tax assets (net) | C13: 34327.8 | D13: 23069.8 | E13: 22850.3
A14: Other non-current assets | C14: 6333.2 | D14: 5434.1 | E14: 5918.8
A15: Total Non-Current Assets | C15: =SUM(C5:C14) -> 372247.4 | D15: =SUM(D5:D14) -> 408596.4 | E15: =SUM(E5:E14) -> 419870.5
A17: Current Assets
A18: Inventories | C18: 89970.2 | D18: 105130.5 | E18: 98682.9
A19: Current investments | C19: 31300.6 | D19: 93726.1 | E19: 85845.4
A20: Trade receivables | C20: 90614 | D20: 114385.1 | E20: 112493.7
A21: Cash & cash equivalents | C21: 62730.3 | D21: 46237.3 | E21: 92856.5
A22: Bank balances (other) | C22: 1724.8 | D22: 11465.6 | E22: 12350.3
A23: Loans (current) | C23: 560.1 | D23: 413.2 | E23: 650.2
A24: Other financial assets (current) | C24: 8759.3 | D24: 7645.1 | E24: 9172
A25: Other current assets | C25: 18761.5 | D25: 19616.5 | E25: 22280.1
A26: Total Current Assets | C26: =SUM(C18:C25) -> 304420.8 | D26: =SUM(D18:D25) -> 398619.4 | E26: =SUM(E18:E25) -> 434331.1
A27: TOTAL ASSETS | C27: =C15+C26 -> 676668.2 | D27: =D15+D26 -> 807215.8 | E27: =E15+E26 -> 854201.6
A29: EQUITY AND LIABILITIES
A30: Equity
A31: Equity share capital | C31: 2399.3 | D31: 2399.3 | E31: 2399.3
A32: Other equity | C32: 462228.5 | D32: 557554.5 | E32: 634268.2
A33: Non-controlling interests | C33: 30170.5 | D33: 33200.9 | E33: 34392.2
A34: Total Equity | C34: =SUM(C31:C33) -> 494798.3 | D34: =SUM(D31:D33) -> 593154.7 | E34: =SUM(E31:E33) -> 671059.7
A36: Non-Current Liabilities
A37: Borrowings (non-current) | C37: 6547.1 | D37: 0 | E37: 13.3
A38: Lease liabilities (NC) | C38: 2434.2 | D38: 5599.1 | E38: 3022.9
A39: Provisions (NC) | C39: 3271.2 | D39: 3429.1 | E39: 4138.9
A40: Deferred tax liabilities | C40: 445.1 | D40: 316.9 | E40: 1550.6
A41: Other non-current liabilities | C41: 7714.9 | D41: 5866.1 | E41: 4999.4
A42: Total Non-Current Liabilities | C42: =SUM(C37:C41) -> 20412.5 | D42: =SUM(D37:D41) -> 15211.2 | E42: =SUM(E37:E41) -> 13725.1
A44: Current Liabilities
...

Sheet Cash Flow Statement
A1: SUN PHARMACEUTICAL INDUSTRIES LTD – CONSOLIDATED CASH FLOW STATEMENT (₹ in Millions)
C2: FY2022 | D2: FY2023 | E2: FY2024
A3: A. CASH FLOW FROM OPERATING ACTIVITIES
A4: Profit before tax | C4: 44813.2 | D4: 94084.3 | E4: 110878.9
A5: Add: Depreciation & amortisation | C5: 21437.4 | D5: 25294.3 | E5: 25566.4
A6: Add: Finance costs | C6: 1273.5 | D6: 1720 | E6: 2384.7
A7: Less: Interest income | C7: -5533.7 | D7: -3845.4 | E7: -10229.1
A8: Less: Dividend income | C8: -2153.3 | D8: -1464.5 | E8: -1033
A9: Fair value (gains)/losses on investments | C9: 3133.4 | D9: -234.1 | E9: -1023.9
A10: Provisions / write-offs & other adjustments | C10: 175.7 | D10: 2070.5 | E10: 905.9
A11: Exchange rate effect | C11: -172 | D11: 3368.1 | E11: -2499.2
A12: Net (gain)/loss on asset disposals | C12: 1656 | D12: 227.1 | E12: 1662.3
A13: Operating profit before working capital changes | C13: =C4+SUM(C5:C12) -> 64630.2 | D13: =D4+SUM(D5:D12) -> 121220.3 | E13: =E4+SUM(E5:E12) -> 126613
A15: Working Capital Movements
A16: (Increase)/Decrease in inventories | C16: 3069.5 | D16: -12022 | E16: 5988.1
A17: (Increase)/Decrease in trade receivables | C17: -13422.6 | D17: -9531.7 | E17: 3528.9
A18: (Increase)/Decrease in other assets | C18: 141.1 | D18: -2158.1 | E18: -3839
A19: Increase/(Decrease) in trade payables | C19: 3699.2 | D19: 11823.7 | E19: 2497.2
A20: Increase/(Decrease) in other liabilities | C20: -23333.5 | D20: -6691.5 | E20: 2409.2
A21: Increase/(Decrease) in provisions | C21: 45436.8 | D21: -38038.6 | E21: 36.9
A22: Cash generated from operations | C22: =C13+SUM(C16:C21) -> 80220.7 | D22: =D13+SUM(D16:D21) -> 64602.1 | E22: =E13+SUM(E16:E21) -> 137234.3
A23: Income tax paid (net) | C23: 9692.2 | D23: -15694.4 | E23: -15098.4
A24: Net Cash from Operating Activities (A) | C24: =C22+C23 -> 89912.9 | D24: =D22+D23 -> 48907.7 | E24: =E22+E23 -> 122135.9
A26: B. CASH FLOW FROM INVESTING ACTIVITIES
A27: Capital expenditure (PPE + intangibles) | C27: -14950.4 | D27: -20855.8 | E27: -22018.1
A28: Proceeds from asset disposals | C28: 606.1 | D28: 210.1 | E28: 308.4
A29: Purchase of investments (net) | C29: -34485.4 | D29: -10673.9 | E29: 10034.3
A30: Fixed deposits movement (net) | C30: -3425.3 | D30: -5762.3 | E30: -709.8
A31: Acquisition of subsidiaries | C31: -7395.7 | D31: -46858.2 | E31: -1433.2
A32: Interest received | C32: 763 | D32: 3179.3 | E32: 6132
A33: Dividend received | C33: 1338.3 | D33: 1324 | E33: 991.4
A34: Net Cash from Investing Activities (B) | C34: =SUM(C27:C33) -> -57549.4 | D34: =SUM(D27:D33) -> -79436.8 | E34: =SUM(E27:E33) -> -6695
A36: C. CASH FLOW FROM FINANCING ACTIVITIES
A37: Proceeds from borrowings | C37: 16567.7 | D37: 81597.8 | E37: 45726.5
A38: Repayment of borrowings | C38: -43999 | D38: -28996.3 | E38: -81055.9
A39: Repayment of lease liabilities | C39: -1286.5 | D39: -1013.8 | E39: -1231
A40: Buyback of NCI shares | C40: -1857 | D40: 0 | E40: -773.9
A41: Net movement in WC demand loans | C41: 1064.2 | D41: -1304.9 | E41: 1430.1
A42: Finance costs paid | C42: -732.1 | D42: -1324.8 | E42: -2190.3
A43: Dividend paid (incl. NCI) | C43: -21691.9 | D43: -25197.3 | E43: -29007.1
...

Sheet Financial Ratios
A1: SUN PHARMACEUTICAL INDUSTRIES LTD – FINANCIAL RATIOS
C2: FY2022 | D2: FY2023 | E2: FY2024
A3: 1. LIQUIDITY RATIOS
A4: Current Ratio (Current Assets ÷ Current Liabilities) | C4: ='Balance Sheet'!C26/'Balance Sheet'!C52 -> 1.8854687 | D4: ='Balance Sheet'!D26/'Balance Sheet'!D52 -> 2.0024706 | E4: ='Balance Sheet'!E26/'Balance Sheet'!E52 -> 2.5573303
A5: OCF Ratio (OCF ÷ Current Liabilities) — ability to cover CL from operations | C5: ='Cash Flow Statement'!C53/'Balance Sheet'!C52 -> 0.55646884 | D5: ='Cash Flow Statement'!D53/'Balance Sheet'!D52 -> 0.24913269 | E5: ='Cash Flow Statement'!E53/'Balance Sheet'!E52 -> 0.71450449
A7: 2. LEVERAGE RATIOS
A8: Debt-to-Equity Ratio ((NC Borrowings + Current Borrowings) ÷ Total Equity) | C8: =('Balance Sheet'!C37+'Balance Sheet'!C45)/'Balance Sheet'!C34 -> 0.071210633 | D8: =('Balance Sheet'!D37+'Balance Sheet'!D45)/'Balance Sheet'!D34 -> 0.10449011 | E8: =('Balance Sheet'!E37+'Balance Sheet'!E45)/'Balance Sheet'!E34 -> 0.042405914
A9: Interest Coverage Ratio (EBIT ÷ Finance Costs) — times interest earned | C9: ='Income Statement'!C22/'Income Statement'!C15 -> 71.049391 | D9: ='Income Statement'!D22/'Income Statement'!D15 -> 55.696977 | E9: ='Income Statement'!E22/'Income Statement'!E15 -> 48.568835
A11: 3. PROFITABILITY & EFFICIENCY RATIOS
A12: Return on Equity – ROE (PAT owners ÷ Total Equity) | C12: ='Income Statement'!C29/'Balance Sheet'!C34 -> 0.066142709 | D12: ='Income Statement'!D29/'Balance Sheet'!D34 -> 0.14285616 | E12: ='Income Statement'!E29/'Balance Sheet'!E34 -> 0.14270534
A13: Days Inventory Outstanding – DIO (Inventory ÷ COGS × 365) | C13: ='Balance Sheet'!C18/('Income Statement'!C11+'Income Statement'!C12+'Income Statement'!C13)*365 -> 317.23901 | D13: ='Balance Sheet'!D18/('Income Statement'!D11+'Income Statement'!D12+'Income Statement'!D13)*365 -> 359.89549 | E13: ='Balance Sheet'!E18/('Income Statement'!E11+'Income Statement'!E12+'Income Statement'!E13)*365 -> 337.80902
A14: Days Sales Outstanding – DSO (Receivables ÷ Revenue from Ops × 365) | C14: ='Balance Sheet'!C20/'Income Statement'!C6*365 -> 85.563436 | D14: ='Balance Sheet'!D20/'Income Statement'!D6*365 -> 95.134817 | E14: ='Balance Sheet'!E20/'Income Statement'!E6*365 -> 84.665706
A15: Days Payables Outstanding – DPO (Payables ÷ COGS × 365) | C15: ='Balance Sheet'!C47/('Income Statement'!C11+'Income Statement'!C12+'Income Statement'!C13)*365 -> 140.11306 | D15: ='Balance Sheet'!D47/('Income Statement'!D11+'Income Statement'!D12+'Income Statement'!D13)*365 -> 194.49669 | E15: ='Balance Sheet'!E47/('Income Statement'!E11+'Income Statement'!E12+'Income Statement'!E13)*365 -> 193.52246
A16: Cash Conversion Cycle – CCC (DIO + DSO − DPO) | C16: =C13+C14-C15 -> 262.68939 | D16: =D13+D14-D15 -> 260.53362 | E16: =E13+E14-E15 -> 228.95227
A18: KEY INPUTS (Linked from Financial Statements)
A19: Revenue from Operations (₹ Mn) | C19: ='Income Statement'!C6 -> 386544.9 | D19: ='Income Statement'!D6 -> 438856.8 | E19: ='Income Statement'!E6 -> 484968.5
A20: EBIT (₹ Mn) | C20: ='Income Statement'!C22 -> 90481.4 | D20: ='Income Statement'!D22 -> 95798.8 | E20: ='Income Statement'!E22 -> 115822.1
A21: PAT attributable to owners (₹ Mn) | C21: ='Income Statement'!C29 -> 32727.3 | D21: ='Income Statement'!D29 -> 84735.8 | E21: ='Income Statement'!E29 -> 95763.8
A22: Operating Cash Flow (₹ Mn) | C22: ='Cash Flow Statement'!C53 -> 89845.4 | D22: ='Cash Flow Statement'!D53 -> 49593.3 | E22: ='Cash Flow Statement'!E53 -> 121349.8
A23: Total Equity (₹ Mn) | C23: ='Balance Sheet'!C34 -> 494798.3 | D23: ='Balance Sheet'!D34 -> 593154.7 | E23: ='Balance Sheet'!E34 -> 671059.7
A24: Total Debt (NC + Current Borrowings) (₹ Mn) | C24: ='Balance Sheet'!C37+'Balance Sheet'!C45 -> 35234.9 | D24: ='Balance Sheet'!D37+'Balance Sheet'!D45 -> 61978.8 | E24: ='Balance Sheet'!E37+'Balance Sheet'!E45 -> 28456.9
